Workbook

Sheet Export original
B1: LUIS T. - S.R.L.
A4: 39100 Bolzano | B4: Tax code | C4: 02274840210
B5: CCIAA number | C5: BZ0167343
A6: Private company
A7: The Global Ultimate Owner of this controlled subsidiary is MR MARKUS BAUMGARTNER
A10: Contact details
A13: Registered office address
A14: WERNER-VON-SIEMENS-STRASSE, 18 | B14: Phone number | C14: 0471095564
A15: 39100 Bolzano | B15: Website address | C15: =HYPERLINK("http://www.luistrenker.com/","www.luistrenker.com") -> www.luistrenker.com
A16: BOLZANO/BOZEN(TRENTINO-ALTO ADIGE/SÜDTIROL)
A18: Trading address
A19: VIA VON SIEMENS 18 | B19: Phone number | C19: 0471095564
A20: 39100 Bolzano
A21: BOLZANO/BOZEN(TRENTINO-ALTO ADIGE)
A24: Legal & account information
A27: Previous name
A28: 08/2012 | B28: LUIS T. - S.R.L. % LUIS T. G.M.B.H.
A29: The date of name change has no legal validity but is the date BvD detected the name change
A31: Legal status | B31: Active | C31: Last accounting closing date | D31: 31/03/2025
A32: Legal form | B32: Limited liability company - SRL
C33: No of available years | D33: 10
A34: Date of incorporation | B34: 37077 | C34: Available accounts | D34: Unconsolidated
C35: Last accounting model | D35: Detailed
A38: Size and group information
A41: Turnover (2025) | B41: 14.885.328 EUR | C41: BvD independence indicator | D41: D
A42: Profit (loss) (2025) | B42: 160.035 EUR
C43: No of companies in corporate group | D43: 7
A44: Total assets (2025) | B44: 12.930.506 EUR
A45: Employees (2025) | B45: 52
C46: No of recorded shareholders | D46: 4
A47: Social capital (2025) | B47: 100 th EUR
C49: No of recorded subsidiaries | D49: 2
A51: Main exchange | B51: Unlisted
A54: Industry classification
A57: Italian trade description | B57: CONFEZIONE DI ARTICOLI DI ABBIGLIAMENTO (ESCLUSO ABBIGLIAMENTO IN LLICCIA)
A59: Ateco 2007 code | B59: 141000 Manufacture of wearing apparel, except fur apparel
A61: SAE code | B61: 430 Imprese produttive
A63: RAE code | B63: 453 Articoli di abbigliamento ed accessori
A66: Peer group
A69: Name | B69: 141 VL (Very large companies)
...

Sheet Balance sheet
A1: Balance sheet
A3: Unconsolidated | B3: 31/03/2020 EUR | C3: 31/03/2021 EUR | D3: 31/03/2022 EUR | E3: 31/03/2023 EUR | F3: 31/03/2024 EUR
B4: 12 months Detailed ICS | C4: 12 months Detailed ICS | D4: 12 months Detailed ICS | E4: 12 months Detailed ICS | F4: 12 months Detailed ICS
A5: Assets
A6: A. TOTAL receivables due from shareholders | B6: 0 | C6: 0 | D6: 0 | E6: 0 | F6: 0
A7: Called share capital | B7: 0 | C7: 0 | D7: 0 | E7: 0 | F7: 0
A9: B. TOTAL FIXED ASSETS | B9: 577699 | C9: 563008 | D9: 836581 | E9: 1533059 | F9: 1597153
A10: B.I. TOTAL INTANGIBLE FIXED ASSETS | B10: 412309 | C10: 348629 | D10: 494303 | E10: 1141024 | F10: 947984
A11: B.I.1. Start-up and expansion costs | B11: 0 | C11: 0 | D11: 0 | E11: 0 | F11: 0
A12: B.I.2. Research and dev. exp. | B12: 0 | C12: 0 | D12: 0 | E12: 0 | F12: 0
A13: B.I.3. Ind. patents and intellect. property rights | B13: 2500 | C13: 7776 | D13: 0 | E13: 502430 | F13: 378595
A14: B.I.4. Concessions, licenses, trademarks and similar rights | B14: 22091 | C14: 24644 | D14: 23054 | E14: 30220 | F14: 31737
A15: B.I.5. Goodwill/Consolidation Difference | B15: 2059 | C15: 1625 | D15: 1190 | E15: 755 | F15: 320
A16: including: Goodwill | B16: 2059 | C16: 1625 | D16: 1190 | E16: 755 | F16: 320
A17: B.I.6. Additions in progress and advances | B17: 0 | C17: 0 | D17: 0 | E17: 0 | F17: 0
A18: B.I.7. Others | B18: 385659 | C18: 314584 | D18: 470059 | E18: 607619 | F18: 537332
A19: (Amortization provision) | B19: n.a. | C19: n.a. | D19: n.a. | E19: n.a. | F19: n.a.
A21: B.II. TOTAL TANGIBLE FIXED ASSETS | B21: 115120 | C21: 164109 | D21: 292008 | E21: 341765 | F21: 598899
A22: including: leased tangible assets | B22: n.a. | C22: n.a. | D22: n.a. | E22: n.a. | F22: n.a.
A23: B.II.1. Land and buildings | B23: 0 | C23: 0 | D23: 0 | E23: 0 | F23: 0
A24: B.II.2. Plant and machinery | B24: 0 | C24: 0 | D24: 0 | E24: 0 | F24: 0
A25: B.II.3. Indust. and commercial equipment | B25: 97013 | C25: 103437 | D25: 271989 | E25: 315454 | F25: 473049
A26: B.II.4. Other assets | B26: 18107 | C26: 60672 | D26: 20019 | E26: 26311 | F26: 125850
A27: B.II.5. Additions in progress and advances | B27: 0 | C27: 0 | D27: 0 | E27: 0 | F27: 0
A28: (Depreciation provision) | B28: n.a. | C28: n.a. | D28: n.a. | E28: n.a. | F28: n.a.
A30: B.III. TOTAL FINANCIAL FIXED ASSETS | B30: 50270 | C30: 50270 | D30: 50270 | E30: 50270 | F30: 50270
A31: including: short term | B31: 0 | C31: 0 | D31: 0 | E31: 0 | F31: 0
A32: B.III.1. Total equity investments | B32: 50270 | C32: 50270 | D32: 50270 | E32: 50270 | F32: 50270
A33: B.III.1.a. Subsidiary companies | B33: 50000 | C33: 50000 | D33: 50000 | E33: 50000 | F33: 50000
A34: B.III.1.b. Associated companies | B34: 0 | C34: 0 | D34: 0 | E34: 0 | F34: 0
A35: B.III.1.c. Parent companies | B35: 0 | C35: 0 | D35: 0 | E35: 0 | F35: 0
A36: B.III.1.d. Companies under parent companies control | B36: 0 | C36: 0 | D36: 0 | E36: 0 | F36: 0
A37: B.III.1.d.bis. Other companies | B37: 270 | C37: 270 | D37: 270 | E37: 270 | F37: 270
A38: B.III.2. Total Receivables | B38: 0 | C38: 0 | D38: 0 | E38: 0 | F38: 0
A39: B.III.2.a. Due from subsidiary comp. | B39: 0 | C39: 0 | D39: 0 | E39: 0 | F39: 0
A40: B.III.2.a. Due from subs. comp. - beyond 12 months | B40: 0 | C40: 0 | D40: 0 | E40: 0 | F40: 0
A41: B.III.2.b. Due from assoc. comp. | B41: 0 | C41: 0 | D41: 0 | E41: 0 | F41: 0
... A82: C.II. RECEIV. DUE WITHIN 12 MONTHS | B82: 3697489 | C82: 3520108 | D82: 5456367 | E82: 5081312 | F82: 6368430
A83: Amounts due for advance taxation | B83: n.a. | C83: n.a. | D83: n.a. | E83: n.a. | F83: n.a.
A84: C.II. RECEIV. DUE BEYOND 12 MONTHS | B84: 0 | C84: 0 | D84: 0 | E84: 0 | F84: 0
...

Sheet Original statements
B1: LUIS T. - S.R.L.
A4: 39100 Bolzano | B4: Tax code | C4: 02274840210
B5: CCIAA number | C5: BZ0167343
A6: Private company
A7: The Global Ultimate Owner of this controlled subsidiary is MR MARKUS BAUMGARTNER
A10: Contact details
A13: Registered office address
A14: WERNER-VON-SIEMENS-STRASSE, 18 | B14: Phone number | C14: 0471095564
A15: 39100 Bolzano | B15: Website address | C15: =HYPERLINK("http://www.luistrenker.com/","www.luistrenker.com") -> www.luistrenker.com
A16: BOLZANO/BOZEN(TRENTINO-ALTO ADIGE/SÜDTIROL)
A18: Trading address
A19: VIA VON SIEMENS 18 | B19: Phone number | C19: 0471095564
A20: 39100 Bolzano
A21: BOLZANO/BOZEN(TRENTINO-ALTO ADIGE)
A24: Legal & account information
A27: Previous name
A28: 08/2012 | B28: LUIS T. - S.R.L. % LUIS T. G.M.B.H.
A29: The date of name change has no legal validity but is the date BvD detected the name change
A31: Legal status | B31: Active | C31: Last accounting closing date | D31: 31/03/2025
A32: Legal form | B32: Limited liability company - SRL
C33: No of available years | D33: 10
A34: Date of incorporation | B34: 37077 | C34: Available accounts | D34: Unconsolidated
C35: Last accounting model | D35: Detailed
A38: Size and group information
A41: Turnover (2025) | B41: 14.885.328 EUR | C41: BvD independence indicator | D41: D
A42: Profit (loss) (2025) | B42: 160.035 EUR
C43: No of companies in corporate group | D43: 7
A44: Total assets (2025) | B44: 12.930.506 EUR
A45: Employees (2025) | B45: 52
C46: No of recorded shareholders | D46: 4
A47: Social capital (2025) | B47: 100 th EUR
C49: No of recorded subsidiaries | D49: 2
A51: Main exchange | B51: Unlisted
A54: Industry classification
A57: Italian trade description | B57: CONFEZIONE DI ARTICOLI DI ABBIGLIAMENTO (ESCLUSO ABBIGLIAMENTO IN LLICCIA)
A59: Ateco 2007 code | B59: 141000 Manufacture of wearing apparel, except fur apparel
A61: SAE code | B61: 430 Imprese produttive
A63: RAE code | B63: 453 Articoli di abbigliamento ed accessori
A66: Peer group
A69: Name | B69: 141 VL (Very large companies)
...

Sheet Reformulated balance sheet
B1: Table 1.e
B3: Luis Trenker S.r.l.
B4: CONSOLIDATED BALANCE SHEET
C5: 2020 | D5: 2021 | E5: 2022 | F5: 2023 | G5: 2024
B6: (in Euro million)
B7: ASSETS
B8: Non-current assets
B9: Concessions | C9: ='Balance sheet'!B14 -> 22091 | D9: ='Balance sheet'!C14 -> 24644 | E9: ='Balance sheet'!D14 -> 23054 | F9: ='Balance sheet'!E14 -> 30220 | G9: ='Balance sheet'!F14 -> 31737
B10: Goodwill | C10: ='Balance sheet'!B15 -> 2059 | D10: ='Balance sheet'!C15 -> 1625 | E10: ='Balance sheet'!D15 -> 1190 | F10: ='Balance sheet'!E15 -> 755 | G10: ='Balance sheet'!F15 -> 320
B11: Other intangible assets | C11: ='Balance sheet'!B11+'Balance sheet'!B12+'Balance sheet'!B17+'Balance sheet'!B18+'Balance sheet'!B13 -> 388159 | D11: ='Balance sheet'!C11+'Balance sheet'!C12+'Balance sheet'!C17+'Balance sheet'!C18+'Balance sheet'!C13 -> 322360 | E11: ='Balance sheet'!D11+'Balance sheet'!D12+'Balance sheet'!D17+'Balance sheet'!D18+'Balance sheet'!D13 -> 470059 | F11: ='Balance sheet'!E11+'Balance sheet'!E12+'Balance sheet'!E17+'Balance sheet'!E18+'Balance sheet'!E13 -> 1110049 | G11: ='Balance sheet'!F11+'Balance sheet'!F12+'Balance sheet'!F17+'Balance sheet'!F18+'Balance sheet'!F13 -> 915927
B12: Tangible fixed assets | C12: =SUM('Balance sheet'!B23:B27) -> 115120 | D12: =SUM('Balance sheet'!C23:C27) -> 164109 | E12: =SUM('Balance sheet'!D23:D27) -> 292008 | F12: =SUM('Balance sheet'!E23:E27) -> 341765 | G12: =SUM('Balance sheet'!F23:F27) -> 598899
B13: Investments | C13: ='Balance sheet'!B30 -> 50270 | D13: ='Balance sheet'!C30 -> 50270 | E13: ='Balance sheet'!D30 -> 50270 | F13: ='Balance sheet'!E30 -> 50270 | G13: ='Balance sheet'!F30 -> 50270
B14: Deferred tax assets | C14: 0 | D14: 0 | E14: 0 | F14: 0 | G14: 0
B15: Other non-current receivables and financial assets | C15: ='Balance sheet'!B67+'Balance sheet'!B69+'Balance sheet'!B71+'Balance sheet'!B73+'Balance sheet'!B75+'Balance sheet'!B77+'Balance sheet'!B79+'Balance sheet'!B81 -> 0 | D15: ='Balance sheet'!C67+'Balance sheet'!C69+'Balance sheet'!C71+'Balance sheet'!C73+'Balance sheet'!C75+'Balance sheet'!C77+'Balance sheet'!C79+'Balance sheet'!C81 -> 0 | E15: ='Balance sheet'!D67+'Balance sheet'!D69+'Balance sheet'!D71+'Balance sheet'!D73+'Balance sheet'!D75+'Balance sheet'!D77+'Balance sheet'!D79+'Balance sheet'!D81 -> 0 | F15: ='Balance sheet'!E67+'Balance sheet'!E69+'Balance sheet'!E71+'Balance sheet'!E73+'Balance sheet'!E75+'Balance sheet'!E77+'Balance sheet'!E79+'Balance sheet'!E81 -> 0 | G15: ='Balance sheet'!F67+'Balance sheet'!F69+'Balance sheet'!F71+'Balance sheet'!F73+'Balance sheet'!F75+'Balance sheet'!F77+'Balance sheet'!F79+'Balance sheet'!F81 -> 0
B16: Total non-current assets | C16: =SUM(C9:C15) -> 577699 | D16: =SUM(D9:D15) -> 563008 | E16: =SUM(E9:E15) -> 836581 | F16: =SUM(F9:F15) -> 1533059 | G16: =SUM(G9:G15) -> 1597153
B17: Current assets
B18: Trade receivables | C18: ='Balance sheet'!B82 -> 3697489 | D18: ='Balance sheet'!C82 -> 3520108 | E18: ='Balance sheet'!D82 -> 5456367 | F18: ='Balance sheet'!E82 -> 5081312 | G18: ='Balance sheet'!F82 -> 6368430
B19: Inventories | C19: ='Balance sheet'!B57 -> 1244471 | D19: ='Balance sheet'!C57 -> 1885278 | E19: ='Balance sheet'!D57 -> 2153497 | F19: ='Balance sheet'!E57 -> 2892260 | G19: ='Balance sheet'!F57 -> 2962879
B20: Cash and cash equivalents | C20: ='Balance sheet'!B101 -> 4873 | D20: ='Balance sheet'!C101 -> 6128 | E20: ='Balance sheet'!D101 -> 9204 | F20: ='Balance sheet'!E101 -> 16924 | G20: ='Balance sheet'!F101 -> 29539
B21: Other current assets and financial current assets | C21: ='Balance sheet'!B99+'Balance sheet'!B103 -> 1307301 | D21: ='Balance sheet'!C99+'Balance sheet'!C103 -> 1276045 | E21: ='Balance sheet'!D99+'Balance sheet'!D103 -> 529833 | F21: ='Balance sheet'!E99+'Balance sheet'!E103 -> 1353543 | G21: ='Balance sheet'!F99+'Balance sheet'!F103 -> 1032729
B22: Total current assets | C22: =SUM(C18:C21) -> 6254134 | D22: =SUM(D18:D21) -> 6687559 | E22: =SUM(E18:E21) -> 8148901 | F22: =SUM(F18:F21) -> 9344039 | G22: =SUM(G18:G21) -> 10393577
B23: Assets held for sale and discounting operations
B24: TOTAL ASSETS | C24: =C16+C22 -> 6831833 | D24: =D16+D22 -> 7250567 | E24: =E16+E22 -> 8985482 | F24: =F16+F22 -> 10877098 | G24: =G16+G22 -> 11990730
B25: EQUITY AND LIABILITIES
B26: Equity
B27: Share Capital | C27: ='Balance sheet'!B113 -> 100000 | D27: ='Balance sheet'!C113 -> 100000 | E27: ='Balance sheet'!D113 -> 100000 | F27: ='Balance sheet'!E113 -> 100000 | G27: ='Balance sheet'!F113 -> 100000
B28: Other reserves | C28: ='Balance sheet'!B120+'Balance sheet'!B123 -> 542433 | D28: ='Balance sheet'!C120+'Balance sheet'!C123 -> 542436 | E28: ='Balance sheet'!D120+'Balance sheet'!D123 -> 542434 | F28: ='Balance sheet'!E120+'Balance sheet'!E123 -> 542436 | G28: ='Balance sheet'!F120+'Balance sheet'!F123 -> 542433
B29: Retained earnings | C29: ='Balance sheet'!B126 -> 0 | D29: ='Balance sheet'!C126 -> 19704 | E29: ='Balance sheet'!D126 -> 324454 | F29: ='Balance sheet'!E126 -> 838262 | G29: ='Balance sheet'!F126 -> 1615043
B30: Group profit (loss) for the period | C30: ='Balance sheet'!B127 -> 19704 | D30: ='Balance sheet'!C127 -> 304750 | E30: ='Balance sheet'!D127 -> 513808 | F30: ='Balance sheet'!E127 -> 776780 | G30: ='Balance sheet'!F127 -> 672289
B31: Total Equity Attributable to Equity Holders of the Parent | C31: =SUM(C27:C30) -> 662137 | D31: =SUM(D27:D30) -> 966890 | E31: =SUM(E27:E30) -> 1480696 | F31: =SUM(F27:F30) -> 2257478 | G31: =SUM(G27:G30) -> 2929765
B32: Non-controlling-interest | C32: 0 | D32: 0 | E32: 0 | F32: 0 | G32: 0
B33: TOTAL CONSOLIDATED EQUITY | C33: =C31 -> 662137 | D33: =D31 -> 966890 | E33: =E31 -> 1480696 | F33: =F31 -> 2257478 | G33: =G31 -> 2929765
B34: Liabilities
B35: Non-current liabilities
B36: Provisions for risks and charges | C36: ='Balance sheet'!B137 -> 0 | D36: ='Balance sheet'!C137 -> 0 | E36: ='Balance sheet'!D137 -> 0 | F36: ='Balance sheet'!E137 -> 0 | G36: ='Balance sheet'!F137 -> 0
B37: Employee benefits | C37: ='Balance sheet'!B144 -> 193620 | D37: ='Balance sheet'!C144 -> 220634 | E37: ='Balance sheet'!D144 -> 253701 | F37: ='Balance sheet'!E144 -> 307482 | G37: ='Balance sheet'!F144 -> 275626
B38: Deferred tax liabilities | C38: 0 | D38: 0 | E38: 0 | F38: 0 | G38: 0
B39: Non-current liabilities to banks and other financial istitutions | C39: ='Balance sheet'!B150+'Balance sheet'!B152+'Balance sheet'!B156+'Balance sheet'!B158+'Balance sheet'!B160+'Balance sheet'!B162+'Balance sheet'!B164+'Balance sheet'!B174+'Balance sheet'!B176+'Balance sheet'!B178 -> 1967673 | D39: ='Balance sheet'!C150+'Balance sheet'!C152+'Balance sheet'!C156+'Balance sheet'!C158+'Balance sheet'!C160+'Balance sheet'!C162+'Balance sheet'!C164+'Balance sheet'!C174+'Balance sheet'!C176+'Balance sheet'!C178 -> 2590830 | E39: ='Balance sheet'!D150+'Balance sheet'!D152+'Balance sheet'!D156+'Balance sheet'!D158+'Balance sheet'!D160+'Balance sheet'!D162+'Balance sheet'!D164+'Balance sheet'!D174+'Balance sheet'!D176+'Balance sheet'!D178 -> 3314910 | F39: ='Balance sheet'!E150+'Balance sheet'!E152+'Balance sheet'!E156+'Balance sheet'!E158+'Balance sheet'!E160+'Balance sheet'!E162+'Balance sheet'!E164+'Balance sheet'!E174+'Balance sheet'!E176+'Balance sheet'!E178 -> 4483132 | G39: ='Balance sheet'!F150+'Balance sheet'!F152+'Balance sheet'!F156+'Balance sheet'!F158+'Balance sheet'!F160+'Balance sheet'!F162+'Balance sheet'!F164+'Balance sheet'!F174+'Balance sheet'!F176+'Balance sheet'!F178 -> 4243554
B40: Other non-current liabilities | C40: ='Balance sheet'!B154 -> 1300000 | D40: ='Balance sheet'!C154 -> 1300000 | E40: ='Balance sheet'!D154 -> 0 | F40: ='Balance sheet'!E154 -> 0 | G40: ='Balance sheet'!F154 -> 0
B41: Total non-current liabilities | C41: =SUM(C36:C40) -> 3461293 | D41: =SUM(D36:D40) -> 4111464 | E41: =SUM(E36:E40) -> 3568611 | F41: =SUM(F36:F40) -> 4790614 | G41: =SUM(G36:G40) -> 4519180
...

Sheet Reformulated Income statement
B1: Table 2.e
B3: Luis Trenker S.r.l.
B4: CONSOLIDATED PROFIT & LOSS
C5: 2020 | D5: 2021 | E5: 2022 | F5: 2023 | G5: 2024
B6: (€ millions)
B7: Revenue | C7: ='Income statement'!B5 -> 10560719 | D7: ='Income statement'!C5 -> 9241787 | E7: ='Income statement'!D5 -> 12660706 | F7: ='Income statement'!E5 -> 14473142 | G7: ='Income statement'!F5 -> 14950204
B8: Total revenues and Operating income | C8: =C7 -> 10560719 | D8: =D7 -> 9241787 | E8: =E7 -> 12660706 | F8: =F7 -> 14473142 | G8: =G7 -> 14950204
B9: Cost of Good Sold | C9: =-'Income statement'!B15 -> -5324267 | D9: =-'Income statement'!C15 -> -4922052 | E9: =-'Income statement'!D15 -> -6273959 | F9: =-'Income statement'!E15 -> -7792575 | G9: =-'Income statement'!F15 -> -6960697
B10: Other operating income (expense) | C10: =-('Income statement'!B16+'Income statement'!B17+'Income statement'!B18+'Income statement'!B34+'Income statement'!B31) -> -4534698 | D10: =-('Income statement'!C16+'Income statement'!C17+'Income statement'!C18+'Income statement'!C34+'Income statement'!C31) -> -3430217 | E10: =-('Income statement'!D16+'Income statement'!D17+'Income statement'!D18+'Income statement'!D34+'Income statement'!D31) -> -4913467 | F10: =-('Income statement'!E16+'Income statement'!E17+'Income statement'!E18+'Income statement'!E34+'Income statement'!E31) -> -5071866 | G10: =-('Income statement'!F16+'Income statement'!F17+'Income statement'!F18+'Income statement'!F34+'Income statement'!F31) -> -6476440
B11: Total depreciation, amortization & depletion | C11: =-'Income statement'!B25 -> -393099 | D11: =-'Income statement'!C25 -> -342652 | E11: =-'Income statement'!D25 -> -584234 | F11: =-'Income statement'!E25 -> -352969 | G11: =-'Income statement'!F25 -> -406658
B12: Total operating expense | C12: =SUM(C9:C11) -> -10252064 | D12: =SUM(D9:D11) -> -8694921 | E12: =SUM(E9:E11) -> -11771660 | F12: =SUM(F9:F11) -> -13217410 | G12: =SUM(G9:G11) -> -13843795
B13: Operating profit (loss) EBIT | C13: =C8+C12 -> 308655 | D13: =D8+D12 -> 546866 | E13: =E8+E12 -> 889046 | F13: =F8+F12 -> 1255732 | G13: =G8+G12 -> 1106409
B14: Finance Revenue | C14: ='Income statement'!B44 -> 584 | D14: ='Income statement'!C44 -> 291 | E14: ='Income statement'!D44 -> 258 | F14: ='Income statement'!E44 -> 333 | G14: ='Income statement'!F44 -> 74265
B15: Finance Expense | C15: =-'Income statement'!B54 -> -191809 | D15: =-'Income statement'!C54 -> -166922 | E15: =-'Income statement'!D54 -> -173690 | F15: =-'Income statement'!E54 -> -240050 | G15: =-'Income statement'!F54 -> -382279
B16: Other non-operating and financial income (expenses) | C16: ='Income statement'!B57 -> -119 | D16: ='Income statement'!C57 -> -62 | E16: ='Income statement'!D57 -> -33 | F16: ='Income statement'!E57 -> -14 | G16: ='Income statement'!F57 -> -46
B17: Financial profit (loss) | C17: =SUM(C14:C16) -> -191344 | D17: =SUM(D14:D16) -> -166693 | E17: =SUM(E14:E16) -> -173465 | F17: =SUM(F14:F16) -> -239731 | G17: =SUM(G14:G16) -> -308060
B18: Financial assets adjustments | C18: ='Income statement'!B59 -> -89095 | D18: 0 | E18: 0 | F18: 0 | G18: 0
B19: Profit (loss) before tax (PBT) | C19: =C13+C17+C18 -> 28216 | D19: =D13+D17 -> 380173 | E19: =E13+E17 -> 715581 | F19: =F13+F17 -> 1016001 | G19: =G13+G17 -> 798349
B20: Income taxes | C20: =-'Income statement'!B82 -> -8512 | D20: =-'Income statement'!C82 -> -75423 | E20: =-'Income statement'!D82 -> -201773 | F20: =-'Income statement'!E82 -> -239221 | G20: =-'Income statement'!F82 -> -126060
B21: NET PROFIT (PAT) | C21: =C19+C20 -> 19704 | D21: =D19+D20 -> 304750 | E21: =E19+E20 -> 513808 | F21: =F19+F20 -> 776780 | G21: =G19+G20 -> 672289
B26: Luis Trenker S.r.l. | J26: Luis Trenker S.r.l.
B27: INCOME STATEMENT - Pre Tax Allocation | J27: INCOME STATEMENT - Pre Tax Allocation | Q27: YEAR TO YEAR GROWTH RATES
C28: 2020 | D28: 2021 | E28: 2022 | F28: 2023 | G28: 2024 | K28: 2020 | L28: 2021 | M28: 2022 | N28: 2023 | O28: 2024 | Q28: 2022 | R28: 2023 | S28: 2024 | T28: CAGR 2021-2024
B29: (€ millions) | J29: (€ millions)
B30: Revenues | C30: =C7 -> 10560719 | D30: =D7 -> 9241787 | E30: =E7 -> 12660706 | F30: =F7 -> 14473142 | G30: =G7 -> 14950204 | J30: Revenues | K30: =C30/$C$30 -> 1 | L30: =D30/$D$30 -> 1 | M30: =E30/$E$30 -> 1 | N30: =F30/$F$30 -> 1 | O30: =G30/$G$30 -> 1 | Q30: =(E30/D30)-1 -> 0.36994133 | R30: =(F30/E30)-1 -> 0.14315442 | S30: =(G30/F30)-1 -> 0.032961882 | T30: =((G30/D30)^(1/3))-1 -> 0.17389807
B31: COGS | C31: =C9 -> -5324267 | D31: =D9 -> -4922052 | E31: =E9 -> -6273959 | F31: =F9 -> -7792575 | G31: =G9 -> -6960697 | J31: COGS | K31: =C31/$C$30 -> -0.50415762 | L31: =D31/$D$30 -> -0.53258661 | M31: =E31/$E$30 -> -0.49554575 | N31: =F31/$F$30 -> -0.53841626 | O31: =G31/$G$30 -> -0.46559211 | Q31: =(E31/D31)-1 -> 0.27466329 | R31: =(F31/E31)-1 -> 0.24205067 | S31: =(G31/F31)-1 -> -0.10675265 | T31: =((G31/D31)^(1/3))-1 -> 0.12245475
B32: Gross Profit | C32: =C30+C31 -> 5236452 | D32: =D30+D31 -> 4319735 | E32: =E30+E31 -> 6386747 | F32: =F30+F31 -> 6680567 | G32: =G30+G31 -> 7989507 | J32: Gross Profit | K32: =C32/$C$30 -> 0.49584238 | L32: =D32/$D$30 -> 0.46741339 | M32: =E32/$E$30 -> 0.50445425 | N32: =F32/$F$30 -> 0.46158374 | O32: =G32/$G$30 -> 0.53440789 | Q32: =(E32/D32)-1 -> 0.47850435 | R32: =(F32/E32)-1 -> 0.046004641 | S32: =(G32/F32)-1 -> 0.19593247 | T32: =((G32/D32)^(1/3))-1 -> 0.22749847
B33: Operating Expenses | C33: =C34 -> -393099 | D33: =D34 -> -342652 | E33: =E34 -> -584234 | F33: =F34 -> -352969 | G33: =G34 -> -406658 | J33: Operating Expenses | K33: =C33/$C$30 -> -0.03722275 | L33: =D33/$D$30 -> -0.037076379 | M33: =E33/$E$30 -> -0.046145452 | N33: =F33/$F$30 -> -0.024387863 | O33: =G33/$G$30 -> -0.027200833 | Q33: =(E33/D33)-1 -> 0.70503601 | R33: =(F33/E33)-1 -> -0.3958431 | S33: =(G33/F33)-1 -> 0.15210684 | T33: =((G33/D33)^(1/3))-1 -> 0.05874657
B34: =B11 -> Total depreciation, amortization & depletion | C34: =C11 -> -393099 | D34: =D11 -> -342652 | E34: =E11 -> -584234 | F34: =F11 -> -352969 | G34: =G11 -> -406658 | J34: =B34 -> Total depreciation, amortization & depletion | K34: =C34/$C$30 -> -0.03722275 | L34: =D34/$D$30 -> -0.037076379 | M34: =E34/$E$30 -> -0.046145452 | N34: =F34/$F$30 -> -0.024387863 | O34: =G34/$G$30 -> -0.027200833 | Q34: =(E34/D34)-1 -> 0.70503601 | R34: =(F34/E34)-1 -> -0.3958431 | S34: =(G34/F34)-1 -> 0.15210684 | T34: =((G34/D34)^(1/3))-1 -> 0.05874657
B35: Core operating Income | C35: =C32+C33 -> 4843353 | D35: =D32+D33 -> 3977083 | E35: =E32+E33 -> 5802513 | F35: =F32+F33 -> 6327598 | G35: =G32+G33 -> 7582849 | J35: Core operating Income | K35: =C35/$C$30 -> 0.45861963 | L35: =D35/$D$30 -> 0.43033701 | M35: =E35/$E$30 -> 0.4583088 | N35: =F35/$F$30 -> 0.43719588 | O35: =G35/$G$30 -> 0.50720706 | Q35: =(E35/D35)-1 -> 0.45898715 | R35: =(F35/E35)-1 -> 0.090492688 | S35: =(G35/F35)-1 -> 0.19837717 | T35: =((G35/D35)^(1/3))-1 -> 0.24000257
B36: Other operating income (expense) | C36: =C10 -> -4534698 | D36: =D10 -> -3430217 | E36: =E10 -> -4913467 | F36: =F10 -> -5071866 | G36: =G10 -> -6476440 | J36: Other operating income (expense) | K36: =C36/$C$30 -> -0.42939292 | L36: =D36/$D$30 -> -0.37116382 | M36: =E36/$E$30 -> -0.38808792 | N36: =F36/$F$30 -> -0.35043296 | O36: =G36/$G$30 -> -0.43320078 | Q36: =(E36/D36)-1 -> 0.43240705 | R36: =(F36/E36)-1 -> 0.032237725 | S36: =(G36/F36)-1 -> 0.27693437 | T36: =((G36/D36)^(1/3))-1 -> 0.23596143
B37: Operating Income | C37: =C35+C36 -> 308655 | D37: =D35+D36 -> 546866 | E37: =E35+E36 -> 889046 | F37: =F35+F36 -> 1255732 | G37: =G35+G36 -> 1106409 | J37: Operating Income | K37: =C37/$C$30 -> 0.029226703 | L37: =D37/$D$30 -> 0.059173188 | M37: =E37/$E$30 -> 0.070220887 | N37: =F37/$F$30 -> 0.086762916 | O37: =G37/$G$30 -> 0.074006281 | Q37: =(E37/D37)-1 -> 0.62571087 | R37: =(F37/E37)-1 -> 0.41244885 | S37: =(G37/F37)-1 -> -0.11891311 | T37: =((G37/D37)^(1/3))-1 -> 0.26477011
B38: Net Interest Income (expense) | C38: =SUM(C39:C42) -> -280439 | D38: =SUM(D39:D41) -> -166693 | E38: =SUM(E39:E41) -> -173465 | F38: =SUM(F39:F41) -> -239731 | G38: =SUM(G39:G41) -> -308060 | J38: Net Interest Income (expense) | K38: =C38/$C$30 -> -0.026554915 | L38: =D38/$D$30 -> -0.01803688 | M38: =E38/$E$30 -> -0.013701053 | N38: =F38/$F$30 -> -0.016563853 | O38: =G38/$G$30 -> -0.020605739 | Q38: =(E38/D38)-1 -> 0.040625581 | R38: =(F38/E38)-1 -> 0.38201366 | S38: =(G38/F38)-1 -> 0.28502363 | T38: =((G38/D38)^(1/3))-1 -> 0.22717354
B39: Financial Income | C39: =C14 -> 584 | D39: =D14 -> 291 | E39: =E14 -> 258 | F39: =F14 -> 333 | G39: =G14 -> 74265 | J39: Financial Income | K39: =C39/$C$30 -> 5.5299265e-05 | L39: =D39/$D$30 -> 3.1487417e-05 | M39: =E39/$E$30 -> 2.0378011e-05 | N39: =F39/$F$30 -> 2.3008135e-05 | O39: =G39/$G$30 -> 0.0049674907 | Q39: =(E39/D39)-1 -> -0.11340206 | R39: =(F39/E39)-1 -> 0.29069767 | S39: =(G39/F39)-1 -> 222.01802 | T39: =((G39/D39)^(1/3))-1 -> 5.3430344
B40: Financial Expense | C40: =C15 -> -191809 | D40: =D15 -> -166922 | E40: =E15 -> -173690 | F40: =F15 -> -240050 | G40: =G15 -> -382279 | J40: Financial Expense | K40: =C40/$C$30 -> -0.018162494 | L40: =D40/$D$30 -> -0.018061658 | M40: =E40/$E$30 -> -0.013718824 | N40: =F40/$F$30 -> -0.016585894 | O40: =G40/$G$30 -> -0.025570153 | Q40: =(E40/D40)-1 -> 0.040545884 | R40: =(F40/E40)-1 -> 0.38205999 | S40: =(G40/F40)-1 -> 0.5924974 | T40: =((G40/D40)^(1/3))-1 -> 0.31812204
B41: =B16 -> Other non-operating and financial income (expenses) | C41: =C16 -> -119 | D41: =D16 -> -62 | E41: =E16 -> -33 | F41: =F16 -> -14 | G41: =G16 -> -46 | J41: Other non operating and financial income(expense) | K41: =C41/$C$30 -> -1.1268172e-05 | L41: =D41/$D$30 -> -6.7086593e-06 | M41: =E41/$E$30 -> -2.6064897e-06 | N41: =F41/$F$30 -> -9.6730896e-07 | O41: =G41/$G$30 -> -3.0768811e-06 | Q41: =(E41/D41)-1 -> -0.46774194 | R41: =(F41/E41)-1 -> -0.57575758 | S41: =(G41/F41)-1 -> 2.2857143 | T41: =((G41/D41)^(1/3))-1 -> -0.094707934
B42: Financial asset adjustments | C42: ='Income statement'!B59 -> -89095 | D42: 0 | E42: 0 | F42: 0 | G42: 0 | J42: Financial asset adjustments | K42: =C42/$C$30 -> -0.0084364521 | L42: =D42/$D$30 -> 0 | M42: =E42/$E$30 -> 0 | N42: =F42/$F$30 -> 0 | O42: =G42/$F$30 -> 0 | Q42: 0 | R42: 0 | S42: 0 | T42: 0
B43: Earnings before Taxes (EBT) | C43: =C37+C38 -> 28216 | D43: =D37+D38 -> 380173 | E43: =E37+E38 -> 715581 | F43: =F37+F38 -> 1016001 | G43: =G37+G38 -> 798349 | J43: Earnings before Taxes (EBT) | K43: =C43/$C$30 -> 0.0026717878 | L43: =D43/$D$30 -> 0.041136308 | M43: =E43/$E$30 -> 0.056519834 | N43: =F43/$F$30 -> 0.070199063 | O43: =G43/$G$30 -> 0.053400542 | Q43: =(E43/D43)-1 -> 0.88225098 | R43: =(F43/E43)-1 -> 0.41982669 | S43: =(G43/F43)-1 -> -0.2142242 | T43: =((G43/D43)^(1/3))-1 -> 0.28057152
B44: Income Tax Expense | C44: =C20 -> -8512 | D44: =D20 -> -75423 | E44: =E20 -> -201773 | F44: =F20 -> -239221 | G44: =G20 -> -126060 | J44: Income Tax Expense | K44: =C44/$C$30 -> -0.00080600573 | L44: =D44/$D$30 -> -0.008161084 | M44: =E44/$E$30 -> -0.015936947 | N44: =F44/$F$30 -> -0.016528616 | O44: =G44/$G$30 -> -0.008431992 | Q44: =(E44/D44)-1 -> 1.6752184 | R44: =(F44/E44)-1 -> 0.1855947 | S44: =(G44/F44)-1 -> -0.47303957 | T44: =((G44/D44)^(1/3))-1 -> 0.18674616
B45: Net Income from continuing operations | C45: =C43+C44 -> 19704 | D45: =D43+D44 -> 304750 | E45: =E43+E44 -> 513808 | F45: =F43+F44 -> 776780 | G45: =G43+G44 -> 672289 | J45: Net Income from continuing operations | K45: =C45/$C$30 -> 0.0018657821 | L45: =D45/$D$30 -> 0.032975224 | M45: =E45/$E$30 -> 0.040582887 | N45: =F45/$F$30 -> 0.053670447 | O45: =G45/$G$30 -> 0.04496855 | Q45: =(E45/D45)-1 -> 0.68599836 | R45: =(F45/E45)-1 -> 0.51180986 | S45: =(G45/F45)-1 -> -0.13451814 | T45: =((G45/D45)^(1/3))-1 -> 0.30177951
...

Sheet Cash flow
P1: Table 3.e
P3: Luis Trenker S.r.l.
B4: CONSOLIDATED PROFIT & LOSS | I4: CONSOLIDATED BALANCE SHEET | P4: REFORMULATED CASH FLOW
C5: 2020 | D5: 2021 | E5: 2022 | F5: 2023 | G5: 2024 | J5: 2020 | K5: 2021 | L5: 2022 | M5: 2023 | N5: 2024 | Q5: 2021 | R5: 20222 | S5: 2023 | T5: 2024
B6: (€ millions) | I6: (in Euro million) | P6: (€ millions)
B7: Revenue | C7: 10560719 | D7: 9241787 | E7: 12660706 | F7: 14473142 | G7: 14950204 | I7: ASSETS | P7: Net income | Q7: =D21 -> 304750 | R7: =E21 -> 513808 | S7: =F21 -> 776780 | T7: =G21 -> 672289
B8: Total revenues and Operating income | C8: 10560719 | D8: 9241787 | E8: 12660706 | F8: 14473142 | G8: 14950204 | I8: Non-current assets | P8: Depreciation and amortization | Q8: =-D11 -> 342652 | R8: =-E11 -> 584234 | S8: =-F11 -> 352969 | T8: =-G11 -> 406658
B9: Cost of Good Sold | C9: -5324267 | D9: -4922052 | E9: -6273959 | F9: -7792575 | G9: -6960697 | I9: Concessions | J9: 22091 | K9: 24644 | L9: 23054 | M9: 30220 | N9: 31737 | O9: x | P9: Changes in working capital
B10: Other operating income (expense) | C10: -4534698 | D10: -3430217 | E10: -4913467 | F10: -5071866 | G10: -6476440 | I10: Goodwill | J10: 2059 | K10: 1625 | L10: 1190 | M10: 755 | N10: 320 | O10: x | P10: Change in trade receivables | Q10: =-(K18-J18) -> 177381 | R10: =-(L18-K18) -> -1936259 | S10: =-(M18-L18) -> 375055 | T10: =-(N18-M18) -> -1287118
B11: Total depreciation, amortization & depletion | C11: -393099 | D11: -342652 | E11: -584234 | F11: -352969 | G11: -406658 | H11: x | I11: Other intangible assets | J11: 388159 | K11: 322360 | L11: 470059 | M11: 1110049 | N11: 915927 | O11: x | P11: Change in inventories | Q11: =-(K19-J19) -> -640807 | R11: =-(L19-K19) -> -268219 | S11: =-(M19-L19) -> -738763 | T11: =-(N19-M19) -> -70619
B12: Total operating expense | C12: -10252064 | D12: -8694921 | E12: -11771660 | F12: -13217410 | G12: -13843795 | I12: Tangible fixed assets | J12: 115120 | K12: 164109 | L12: 292008 | M12: 341765 | N12: 598899 | O12: x | P12: Change in other current assets | Q12: =-(K21-J21) -> 31256 | R12: =-(L21-K21) -> 746212 | S12: =-(M21-L21) -> -823710 | T12: =-(N21-M21) -> 320814
B13: Operating profit (loss) EBIT | C13: 308655 | D13: 546866 | E13: 889046 | F13: 1255732 | G13: 1106409 | I13: Investments | J13: 50270 | K13: 50270 | L13: 50270 | M13: 50270 | N13: 50270 | O13: x | P13: Change in trade payables | Q13: =K46-J46 -> -24329 | R13: =L46-K46 -> 746745 | S13: =M46-L46 -> 74011 | T13: =N46-M46 -> -584804
B14: Finance Revenue | C14: 584 | D14: 291 | E14: 258 | F14: 333 | G14: 74265 | I14: Deferred tax assets | J14: 0 | K14: 0 | L14: 0 | M14: 0 | N14: 0 | O14: x
B15: Finance Expense | C15: -191809 | D15: -166922 | E15: -173690 | F15: -240050 | G15: -382279 | I15: Other non-current receivables and financial assets | J15: 0 | K15: 0 | L15: 0 | M15: 0 | N15: 0 | O15: x | P15: change in current tax | Q15: =K48-J48 -> 17706 | R15: =L48-K48 -> 112101 | S15: =M48-L48 -> -79920 | T15: =N48-M48 -> 29474
B16: Other non-operating and financial income (expenses) | C16: -119 | D16: -62 | E16: -33 | F16: -14 | G16: -46 | I16: Total non-current assets | J16: 577699 | K16: 563008 | L16: 836581 | M16: 1533059 | N16: 1597153 | P16: Change in other current liabilities | Q16: =K49-J49 -> 16482 | R16: =L49-K49 -> 138986 | S16: =M49-L49 -> 179426 | T16: =N49-M49 -> 94321
B17: Financial profit (loss) | C17: -191344 | D17: -166693 | E17: -173465 | F17: -239731 | G17: -308060 | I17: Current assets | P17: Cash flow from operating activities | Q17: =SUM(Q7:Q16) -> 225091 | R17: =SUM(R7:R16) -> 637608 | S17: =SUM(S7:S16) -> 115848 | T17: =SUM(T7:T16) -> -418985
B18: Financial assets adjustments | C18: -89095 | D18: 0 | E18: 0 | F18: 0 | G18: 0 | I18: Trade receivables | J18: 3697489 | K18: 3520108 | L18: 5456367 | M18: 5081312 | N18: 6368430 | O18: x
B19: Profit (loss) before tax (PBT) | C19: 28216 | D19: 380173 | E19: 715581 | F19: 1016001 | G19: 798349 | I19: Inventories | J19: 1244471 | K19: 1885278 | L19: 2153497 | M19: 2892260 | N19: 2962879 | O19: x | P19: Purchase of PPE | Q19: =-((K12-D11)-(J12-C11)) -> 1458 | R19: =-((L12-E11)-(K12-D11)) -> -369481 | S19: =-((M12-F11)-(L12-E11)) -> 181508 | T19: =-((N12-G11)-(M12-F11)) -> -310823
B20: Income taxes | C20: -8512 | D20: -75423 | E20: -201773 | F20: -239221 | G20: -126060 | I20: Cash and cash equivalents | J20: 4873 | K20: 6128 | L20: 9204 | M20: 16924 | N20: 29539 | P20: Purchase of other LT investments | Q20: =-(K13-J13+K15-J15) -> 0 | R20: =-(L13-K13+L15-K15) -> 0 | S20: =-(M13-L13+M15-L15) -> 0 | T20: =-(N13-M13+N15-M15) -> 0
B21: NET PROFIT (PAT) | C21: 19704 | D21: 304750 | E21: 513808 | F21: 776780 | G21: 672289 | H21: x | I21: Other current assets and financial current assets | J21: 1307301 | K21: 1276045 | L21: 529833 | M21: 1353543 | N21: 1032729 | O21: x | P21: Other assets | Q21: =-(K9-J9+K10-J10+K11-J11+K14-J14) -> 63680 | R21: =-(L9-K9+L10-K10+L11-K11+L14-K14) -> -145674 | S21: =-(M9-L9+M10-L10+M11-L11+M14-L14) -> -646721 | T21: =-(N9-M9+N10-M10+N11-M11+N14-M14) -> 193040
I22: Total current assets | J22: 6254134 | K22: 6687559 | L22: 8148901 | M22: 9344039 | N22: 10393577 | P22: Cash flow from investing activities | Q22: =SUM(Q19:Q21) -> 65138 | R22: =SUM(R19:R21) -> -515155 | S22: =SUM(S19:S21) -> -465213 | T22: =SUM(T19:T21) -> -117783
I23: Assets held for sale and discounting operations
I24: TOTAL ASSETS | J24: 6831833 | K24: 7250567 | L24: 8985482 | M24: 10877098 | N24: 11990730 | P24: Increase in long term liabilities | Q24: =K42-J42 -> 623157 | R24: =L42-K42 -> 724080 | S24: =M42-L42 -> 1168222 | T24: =N42-M42 -> -239578
P25: Change in current liabilities for banks and loans | Q25: =K47-J47 -> -546049 | R25: =L47-K47 -> 766130 | S25: =M47-L47 -> -280686 | T25: =N47-M47 -> 1173788
I26: EQUITY AND LIABILITIES | P26: Decrease in other long term liabilities | Q26: =K43-J43+K41-J41+K40-J40+K39-J39 -> 27014 | R26: =L43-K43+L41-K41+L40-K40+L39-K39 -> -1266933 | S26: =M43-L43+M41-L41+M40-L40+M39-L39 -> 53781 | T26: =N43-M43+N41-M41+N40-M40+N39-M39 -> -31856
I27: Equity | P27: Proceeds from share issuance | Q27: =K28-J28 -> 0 | R27: =L28-K28 -> 0 | S27: =M28-L28 -> 0 | T27: =N28-M28 -> 0
I28: Share Capital | J28: 100000 | K28: 100000 | L28: 100000 | M28: 100000 | N28: 100000 | O28: x | P28: Cash flow from financing activities | Q28: =SUM(Q24:Q27) -> 104122 | R28: =SUM(R24:R27) -> 223277 | S28: =SUM(S24:S27) -> 941317 | T28: =SUM(T24:T27) -> 902354
I29: Other reserves | J29: 542433 | K29: 542436 | L29: 542434 | M29: 542436 | N29: 542433
I30: Retained earnings | J30: 0 | K30: 19704 | L30: 324454 | M30: 838262 | N30: 1615043 | P30: Net change in cash actual | Q30: =Q37-Q35 -> 1255 | R30: =R37-R35 -> 3076 | S30: =S37-S35 -> 7720 | T30: =T37-T35 -> 12615
P31: Net change in cash computed | Q31: =Q28+Q22+Q17 -> 394351 | R31: =R28+R22+R17 -> 345730 | S31: =S28+S22+S17 -> 591952 | T31: =T28+T22+T17 -> 365586
P32: Adjustment for cash flow recoinciliation | Q32: =Q30-Q31 -> -393096 | R32: =R30-R31 -> -342654 | S32: =S30-S31 -> -584232 | T32: =T30-T31 -> -352971
I33: Group profit (loss) for the period | J33: 19704 | K33: 304750 | L33: 513808 | M33: 776780 | N33: 672289 | P33: Adjusted net change in cash computed | Q33: =Q31+Q32 -> 1255 | R33: =R31+R32 -> 3076 | S33: =S31+S32 -> 7720 | T33: =T31+T32 -> 12615
I34: Total Equity Attributable to Equity Holders of the Parent | J34: 662137 | K34: 966890 | L34: 1480696 | M34: 2257478 | N34: 2929765
I35: Non-controlling-interest | J35: 0 | K35: 0 | L35: 0 | M35: 0 | N35: 0 | P35: Beginning | Q35: =J20 -> 4873 | R35: =K20 -> 6128 | S35: =L20 -> 9204 | T35: =M20 -> 16924
I36: TOTAL CONSOLIDATED EQUITY | J36: 662137 | K36: 966890 | L36: 1480696 | M36: 2257478 | N36: 2929765 | P36: Ending computed | Q36: =Q33+Q35 -> 6128 | R36: =R33+R35 -> 9204 | S36: =S33+S35 -> 16924 | T36: =T33+T35 -> 29539
I37: Liabilities | P37: Ending actual | Q37: =K20 -> 6128 | R37: =L20 -> 9204 | S37: =M20 -> 16924 | T37: =N20 -> 29539
I38: Non-current liabilities
I39: Provisions for risks and charges | J39: 0 | K39: 0 | L39: 0 | M39: 0 | N39: 0 | O39: x
I40: Employee benefits | J40: 193620 | K40: 220634 | L40: 253701 | M40: 307482 | N40: 275626 | O40: x
I41: Deferred tax liabilities | J41: 0 | K41: 0 | L41: 0 | M41: 0 | N41: 0 | O41: x
...

Sheet Ratio
B1: Luis Trenker
B2: ADDITIONAL INFORMATION FOR PROFITABILITY ANALYSIS
E3: 2021 | F3: 2022 | G3: 2023 | H3: 2024
B4: OA | C4: Operating Assets | E4: ='[1]Reformulated balance sheet'!D63 -> 6766164 | F4: ='[1]Reformulated balance sheet'!E63 -> 8845278 | G4: ='[1]Reformulated balance sheet'!F63 -> 10164691 | H4: ='[1]Reformulated balance sheet'!G63 -> 11515958
B5: OL | C5: Operating Liabilites | E5: ='[1]Reformulated balance sheet'!D76 -> 1763860 | F5: ='[1]Reformulated balance sheet'!E76 -> 2761692 | G5: ='[1]Reformulated balance sheet'!F76 -> 2935209 | H5: ='[1]Reformulated balance sheet'!G76 -> 2474200
B6: NOA | C6: Net Operating Assets | E6: =E4-E5 -> 5002304 | F6: =F4-F5 -> 6083586 | G6: =G4-G5 -> 7229482 | H6: =H4-H5 -> 9041758
B7: FA | C7: Total Financial Assets | E7: ='[1]Reformulated balance sheet'!D67 -> 484403 | F7: ='[1]Reformulated balance sheet'!E67 -> 140204 | G7: ='[1]Reformulated balance sheet'!F67 -> 712407 | H7: ='[1]Reformulated balance sheet'!G67 -> 474772
B8: FL | C8: Financial Liabilities | E8: ='[1]Reformulated balance sheet'!D83 -> 4519817 | F8: ='[1]Reformulated balance sheet'!E83 -> 4743094 | G8: ='[1]Reformulated balance sheet'!F83 -> 5684411 | H8: ='[1]Reformulated balance sheet'!G83 -> 6586765
B9: NFO (NFA) | C9: Net Financial Obligation (Net Financial Assets) | E9: =E8-E7 -> 4035414 | F9: =F8-F7 -> 4602890 | G9: =G8-G7 -> 4972004 | H9: =H8-H7 -> 6111993
C10: Equity | E10: ='[1]Reformulated balance sheet'!D89 -> 966890 | F10: ='[1]Reformulated balance sheet'!E89 -> 1480696 | G10: ='[1]Reformulated balance sheet'!F89 -> 2257478 | H10: ='[1]Reformulated balance sheet'!G89 -> 2929765
B11: NOA | C11: Average NOA | F11: =(F6+E6)/2 -> 5542945 | G11: =(G6+F6)/2 -> 6656534 | H11: =(H6+G6)/2 -> 8135620
C12: Average Total Financial Assets | F12: =(F7+E7)/2 -> 312303.5 | G12: =(G7+F7)/2 -> 426305.5 | H12: =(H7+G7)/2 -> 593589.5
C13: Average Total Financial Liabilities | F13: =(F8+E8)/2 -> 4631455.5 | G13: =(G8+F8)/2 -> 5213752.5 | H13: =(H8+G8)/2 -> 6135588
B14: NFO (NFA) | C14: Average Net Financial Obligation (Net Financial Assets) | F14: =(F9+E9)/2 -> 4319152 | G14: =(G9+F9)/2 -> 4787447 | H14: =(H9+G9)/2 -> 5541998.5
B15: EQUITY | C15: Average Equity | F15: =(F10+E10)/2 -> 1223793 | G15: =(G10+F10)/2 -> 1869087 | H15: =(H10+G10)/2 -> 2593621.5
C16: Account Receivable | E16: ='[1]Reformulated balance sheet'!D56 -> 1192500 | F16: ='[1]Reformulated balance sheet'!E56 -> 1268047 | G16: ='[1]Reformulated balance sheet'!F56 -> 1367114 | H16: ='[1]Reformulated balance sheet'!G56 -> 899391
C17: Inventory | E17: ='[1]Reformulated balance sheet'!D57 -> 1885278 | F17: ='[1]Reformulated balance sheet'!E57 -> 2153497 | G17: ='[1]Reformulated balance sheet'!F57 -> 2892260 | H17: ='[1]Reformulated balance sheet'!G57 -> 2962879
C18: Accounts Payable | E18: ='[1]Reformulated balance sheet'!D71 -> 1023644 | F18: ='[1]Reformulated balance sheet'!E71 -> 1770389 | G18: ='[1]Reformulated balance sheet'!F71 -> 1844400 | H18: ='[1]Reformulated balance sheet'!G71 -> 1259596
C19: Average Account Receivable | F19: =(F16+E16)/2 -> 1230273.5 | G19: =(G16+F16)/2 -> 1317580.5 | H19: =(H16+G16)/2 -> 1133252.5
C20: Average Inventory | F20: =(F17+E17)/2 -> 2019387.5 | G20: =(G17+F17)/2 -> 2522878.5 | H20: =(H17+G17)/2 -> 2927569.5
C21: Average Accounts Payable | F21: =(F18+E18)/2 -> 1397016.5 | G21: =(G18+F18)/2 -> 1807394.5 | H21: =(H18+G18)/2 -> 1551998
C22: Revenues | E22: ='[1]Reformulated Income statement'!D5 -> 9241787 | F22: ='[1]Reformulated Income statement'!E5 -> 12660706 | G22: ='[1]Reformulated Income statement'!F5 -> 14473142 | H22: ='[1]Reformulated Income statement'!G5 -> 14950204
C23: COGS (manufacturing) or Cost of Sales (other industries) | E23: ='[1]Reformulated Income statement'!D7 -> -4922052 | F23: ='[1]Reformulated Income statement'!E7 -> -6273959 | G23: ='[1]Reformulated Income statement'!F7 -> -7792575 | H23: ='[1]Reformulated Income statement'!G7 -> -6960697
C24: Gross Profit | E24: =E22+E23 -> 4319735 | F24: =F22+F23 -> 6386747 | G24: =G22+G23 -> 6680567 | H24: =H22+H23 -> 7989507
B25: NOPAT CORE | C25: Core Operating Income from sales (After tax effect) | E25: ='[1]Reformulated Income statement'!D72 -> -60840.5 | F25: ='[1]Reformulated Income statement'!E72 -> 317391.31 | G25: ='[1]Reformulated Income statement'!F72 -> 65251.228 | H25: ='[1]Reformulated Income statement'!G72 -> 881265.58
B26: UI | C26: Unusual Item (after tax effect)
B27: NOPAT | C27: NOPAT | E27: ='[1]Reformulated Income statement'!D76 -> 438372.57 | F27: ='[1]Reformulated Income statement'!E76 -> 638360.92 | G27: ='[1]Reformulated Income statement'!F76 -> 960065.49 | H27: ='[1]Reformulated Income statement'!G76 -> 931706.06
C28: Financial Income (after tax effect) | E28: ='[1]Reformulated Income statement'!D78 -> 291 | F28: ='[1]Reformulated Income statement'!E78 -> 258 | G28: ='[1]Reformulated Income statement'!F78 -> 333 | H28: ='[1]Reformulated Income statement'!G78 -> 74265
C29: Financial Expenses (after tax effect) | E29: ='[1]Reformulated Income statement'!D79 -> -166922 | F29: ='[1]Reformulated Income statement'!E79 -> -173690 | G29: ='[1]Reformulated Income statement'!F79 -> -240050 | H29: ='[1]Reformulated Income statement'!G79 -> -382279
B30: NFE | C30: Net financial expense (income) after tax | E30: ='[1]Reformulated Income statement'!D83 -> -133622.57 | F30: ='[1]Reformulated Income statement'!E83 -> -124552.92 | G30: ='[1]Reformulated Income statement'!F83 -> -183285.49 | H30: ='[1]Reformulated Income statement'!G83 -> -259417.06
C31: EBT | E31: ='[1]Reformulated Income statement'!D44 -> 380173 | F31: ='[1]Reformulated Income statement'!E44 -> 715581 | G31: ='[1]Reformulated Income statement'!F44 -> 1016001 | H31: ='[1]Reformulated Income statement'!G44 -> 798349
C32: Net Income from continuing operations | E32: ='[1]Reformulated Income statement'!D46 -> 304750 | F32: ='[1]Reformulated Income statement'!E46 -> 513808 | G32: ='[1]Reformulated Income statement'!F46 -> 776780 | H32: ='[1]Reformulated Income statement'!G46 -> 672289
C33: Net Income | E33: ='[1]Reformulated Income statement'!D50 -> 304750 | F33: ='[1]Reformulated Income statement'!E50 -> 513808 | G33: ='[1]Reformulated Income statement'!F50 -> 776780 | H33: ='[1]Reformulated Income statement'!G50 -> 672289
C34: Net Income attribuitable to common shareholder
C35: Gross Tangible Assets | E35: ='[1]Reformulated balance sheet'!D58 -> 164109 | F35: ='[1]Reformulated balance sheet'!E58 -> 292008 | G35: ='[1]Reformulated balance sheet'!F58 -> 341765 | H35: ='[1]Reformulated balance sheet'!G58 -> 598899
C36: Depreciation | E36: ='[1]Income statement'!C27 -> 44125 | F36: ='[1]Income statement'!D27 -> 50982 | G36: ='[1]Income statement'!E27 -> 65514 | H36: ='[1]Income statement'!F27 -> 104667
C37: Accumulated Depreciation | F37: =F36-E36 -> 6857 | G37: =G36-F36 -> 14532 | H37: =H36-G36 -> 39153
C38: PP&E net | E38: =E35-E36 -> 119984 | F38: =F35-F36 -> 241026 | G38: =G35-G36 -> 276251 | H38: =H35-H36 -> 494232
C39: Average Assets | F39: =('[1]Reformulated balance sheet'!E21+'[1]Reformulated balance sheet'!D21)/2 -> 8118024.5 | G39: =('[1]Reformulated balance sheet'!F21+'[1]Reformulated balance sheet'!E21)/2 -> 9931290 | H39: =('[1]Reformulated balance sheet'!G21+'[1]Reformulated balance sheet'!F21)/2 -> 11433914
B41: Table 4.e
...

Sheet Income statement
A1: Profit and loss account
A2: thousands of euros
A3: Unconsolidated | B3: 31/03/2020 EUR | C3: 31/03/2021 EUR | D3: 31/03/2022 EUR | E3: 31/03/2023 EUR | F3: 31/03/2024 EUR
B4: 12 months Detailed ICS | C4: 12 months Detailed ICS | D4: 12 months Detailed ICS | E4: 12 months Detailed ICS | F4: 12 months Detailed ICS
A5: A. TOTAL VALUE OF PRODUCTION | B5: 10560719 | C5: 9241787 | D5: 12660706 | E5: 14473142 | F5: 14950204
A6: A.1. Revenues from sales and services | B6: 9712939 | C6: 8552816 | D6: 11619465 | E6: 13782014 | F6: 14294364
A7: A.2. Changes in inventories | B7: 0 | C7: 0 | D7: 0 | E7: 0 | F7: 0
A8: A.3. Changes in contract work in progress | B8: 0 | C8: 0 | D8: 0 | E8: 0 | F8: 0
A9: A.2. + A.3. Total changes | B9: 0 | C9: 0 | D9: 0 | E9: 0 | F9: 0
A10: A.4. Additions to fixed assets | B10: 0 | C10: 0 | D10: 0 | E10: 0 | F10: 0
A11: A.5. Other revenue | B11: 847780 | C11: 688971 | D11: 1041241 | E11: 691128 | F11: 655840
A12: operating grants | B12: 641183 | C12: 260024 | D12: 445901 | E12: 404719 | F12: 360311
A14: B. TOTAL PRODUCTION COSTS | B14: 10252064 | C14: 8694921 | D14: 11771660 | E14: 13217410 | F14: 13843795
A15: B.6. Raw, consum. mat. and goods for resale | B15: 5324267 | C15: 4922052 | D15: 6273959 | E15: 7792575 | F15: 6960697
A16: B.7. Services | B16: 2733445 | C16: 2242963 | D16: 2473024 | E16: 2871646 | F16: 3194159
A17: B.8. Use of third parties assets | B17: 508533 | C17: 357317 | D17: 562664 | E17: 740801 | F17: 873725
... A40: C.15. Total income from equity investments | B40: 0 | C40: 0 | D40: 0 | E40: 0 | F40: 0
A41: of which: from subsidiaries, associated, parent cies and cies under parent cies control | B41: n.a. | C41: n.a. | D41: n.a. | E41: n.a. | F41: n.a.
A42: of which: from parent companies | B42: 0 | C42: 0 | D42: 0 | E42: 0 | F42: 0
A43: of which: from companies under parent companies control | B43: 0 | C43: 0 | D43: 0 | E43: 0 | F43: 0
A44: C.16. Total other financial income | B44: 584 | C44: 291 | D44: 258 | E44: 333 | F44: 74265
A45: C.16.a. From financial receivables | B45: 0 | C45: 0 | D45: 0 | E45: 0 | F45: 0
A46: of which: from subsidiaries, associated, parent cies and cies under parent cies control | B46: n.a. | C46: n.a. | D46: n.a. | E46: n.a. | F46: n.a.
A47: of which: from companies under parent companies control | B47: 0 | C47: 0 | D47: 0 | E47: 0 | F47: 0
A48: C.16.b. From securities held as fixed assets | B48: 0 | C48: 0 | D48: 0 | E48: 0 | F48: 0
A49: C.16.c. From securities held as current assets | B49: 0 | C49: 0 | D49: 0 | E49: 0 | F49: 0
A50: C.16.b+c. From securities | B50: 0 | C50: 0 | D50: 0 | E50: 0 | F50: 0
A51: C.16.d. Income other than the above | B51: 584 | C51: 291 | D51: 258 | E51: 333 | F51: 74265
A52: of which: from subsidiaries, associated, parent cies and cies under parent cies control | B52: n.a. | C52: 0 | D52: 0 | E52: 0 | F52: 0
A53: of which: from companies under parent companies control | B53: 0 | C53: 0 | D53: 0 | E53: 0 | F53: 0
A54: C.17. Total financial charges | B54: 191809 | C54: 166922 | D54: 173690 | E54: 240050 | F54: 382279
A55: of which: from financial receivables subs and assoc. | B55: n.a. | C55: 0 | D55: 0 | E55: 0 | F55: 0
A56: of which: from companies under parent companies control | B56: 0 | C56: 0 | D56: 0 | E56: 0 | F56: 0
A57: C.17.bis Profit and Loss on Foreign Exchange | B57: -119 | C57: -62 | D57: -33 | E57: -14 | F57: -46
A59: D. TOTAL FINANCIAL ASSETS ADJUSTMENTS | B59: -89095 | C59: 0 | D59: 0 | E59: 0 | F59: 0
A60: D.18. Total Revaluations | B60: 0 | C60: 0 | D60: 0 | E60: 0 | F60: 0
A61: D.18.a. Reval. of equity investments | B61: 0 | C61: 0 | D61: 0 | E61: 0 | F61: 0
A62: D.18.b. Reval. of other financial assets | B62: 0 | C62: 0 | D62: 0 | E62: 0 | F62: 0
A63: D.18.c. Reval. of securities | B63: 0 | C63: 0 | D63: 0 | E63: 0 | F63: 0
A64: D.18.d. Reval. of derivatives | B64: 0 | C64: 0 | D64: 0 | E64: 0 | F64: 0
...

Sheet Ratios
A1: Ratios
B3: Unconsolidated | C3: 31/03/2024 EUR | D3: 31/03/2023 EUR | E3: 31/03/2022 EUR | F3: 31/03/2021 EUR | G3: 31/03/2020 EUR | H3: 31/03/2019 EUR
C4: 12 months Detailed ICS | D4: 12 months Detailed ICS | E4: 12 months Detailed ICS | F4: 12 months Detailed ICS | G4: 12 months Detailed ICS | H4: 12 months Detailed ICS
B5: 1. Financial indicators
B7: - Liquidity ratio | C7: 1.61 | D7: 1.63 | E7: 1.49 | F7: 1.99 | G7: 1.48 | H7: 1.18
B8: - Current ratio | C8: 2.31 | D8: 2.45 | E8: 2.07 | F8: 2.94 | G8: 1.97 | H8: 1.46
B9: - Current liabilities/Tot ass. | C9: 0.5 | D9: 0.44 | E9: 0.53 | F9: 0.34 | G9: 0.44 | H9: 0.56
B10: - Long/med term liab/Tot ass. | C10: 0.5 | D10: 0.56 | E10: 0.47 | F10: 0.66 | G10: 0.56 | H10: 0.44
B11: - Tang. fixed ass./Share funds | C11: 0.2 | D11: 0.15 | E11: 0.2 | F11: 0.17 | G11: 0.17 | H11: 0.18
B12: - Depr./Tang. fixed assets | C12: n.a. | D12: n.a. | E12: n.a. | F12: n.a. | G12: n.a. | H12: n.a.
B13: - Leverage | C13: 4.09 | D13: 4.82 | E13: 6.07 | F13: 7.5 | G13: 10.32 | H13: 11.2
B14: - Coverage of fixed assets | C14: 4.49 | D14: 4.4 | E14: 5.73 | F14: 8.63 | G14: 6.8 | H14: 4.91
B15: - Banks/Turnover | C15: 35.17 | D15: 28.68 | E15: 25.19 | F15: 32.45 | G15: 27.67 | H15: 25.15
B16: - Cost of debit | C16: 7.27 | D16: 5.78 | E16: 5.45 | F16: 5.57 | G16: 6.56 | H16: 5.98
B17: - Interest/Operating profit | C17: 3.96 | D17: 6.7 | E17: 8.48 | F17: 5.33 | G17: 3.66 | H17: 3.72
B18: - Interest/Turnover | C18: 2.56 | D18: 1.66 | E18: 1.37 | F18: 1.81 | G18: 1.82 | H18: 1.5
B19: - Solvency ratio | C19: 24.43 | D19: 20.75 | E19: 16.48 | F19: 13.34 | G19: 9.69 | H19: 8.93
B20: - Share funds/Liabilities | C20: 0.35 | D20: 0.28 | E20: 0.21 | F20: 0.16 | G20: 0.11 | H20: 0.1
B21: - Net Financial Position | C21: 5886637 | D21: 4714792 | E21: 4399459 | F21: 2565050 | G21: 2849112 | H21: 3938981
B22: - Debt/Equity ratio | C22: 2.15 | D22: 2.38 | E22: 3.03 | F22: 3.1 | G22: 4.41 | H22: 6.2
B23: - Debt/EBITDA ratio | C23: 4.17 | D23: 3.34 | E23: 3.05 | F23: 3.37 | G23: 4.16 | H23: 6.68
B25: 2. Management ratios
B27: - Total assets turnover (times) | C27: 1.19 | D27: 1.27 | E27: 1.29 | F27: 1.18 | G27: 1.42 | H27: 1.42
B28: - Working cap. turnover (times) | C28: 1.47 | D28: 1.6 | E28: 1.51 | F28: 1.46 | G28: 1.94 | H28: 2
B29: - Incidenza circolante operativo | C29: 17.41 | D29: 16.69 | E29: 13.04 | F29: 22.23 | G29: 23.88 | H29: 21.71
B30: - Stocks/Turnover (days) | C30: 72.34 | D30: 72.94 | E30: 62.08 | F30: 74.46 | G30: 43.01 | H30: 33.29
B31: - Stocks/Cost goods sold (days) | C31: 156.96 | D31: 149.66 | E31: 130.88 | F31: 160.73 | G31: 89.9 | H31: 64.85
B32: - Durata media dei crediti al lordo IVA (days) | C32: 21.96 | D32: 34.48 | E32: 36.56 | F32: 47.1 | G32: 80.38 | H32: 91.73
B33: - Durata media dei debiti al lordo IVA (days) | C33: 41.69 | D33: 59.03 | E33: 69.41 | F33: 49.67 | G33: 44.65 | H33: 54.12
B34: - Durata Ciclo Commerciale (days) | C34: 137.23 | D34: 125.11 | E34: 98.03 | F34: 158.16 | G34: 125.63 | H34: 102.46
B36: 3. Profitability ratios
B38: - EBITDA | C38: 1513067 | D38: 1608701 | E38: 1473280 | F38: 889518 | G38: 701754 | H38: 595594
B39: - EBITDA/Vendite | C39: 10.12 | D39: 11.12 | E39: 11.64 | F39: 9.62 | G39: 6.64 | H39: 5.59
B40: - Return on asset (ROA) | C40: 9.23 | D40: 11.54 | E40: 9.89 | F40: 7.54 | G40: 4.52 | H40: 6.75
B41: - Return on investment (ROI) | C41: 11.97 | D41: 16.45 | E41: 14.89 | F41: 10.38 | G41: 6.32 | H41: 10.5
B42: - Return on sales (ROS) | C42: 7.4 | D42: 8.68 | E42: 7.02 | F42: 5.92 | G42: 2.92 | H42: 4.56
B43: - Return on equity (ROE) | C43: 22.95 | D43: 34.41 | E43: 34.7 | F43: 31.52 | G43: 2.98 | H43: 32.6
B44: - Net P&L / Operating P&L | C44: 60.76 | D44: 61.86 | E44: 57.79 | F44: 55.73 | G44: 6.38 | H44: 43.14
B46: 4. Productivity ratios
B48: - Number of employees | C48: 48 | D48: 42 | E48: 40 | F48: 38 | G48: 36 | H48: 25
...
